{
 "cells": [
  {
   "cell_type": "markdown",
   "metadata": {
    "slideshow": {
     "slide_type": "slide"
    }
   },
   "source": [
    "# Exceptions\n",
    "Python uses special objects called exceptions to manage errors that arise during a program’s execution. Whenever an error occurs that makes Python unsure what to do next, it creates an exception object. If you write code that handles the exception, the program will continue running. If you do not handle the exception, the program will halt and show a traceback, which includes a report of the exception that was raised.\n",
    "\n",
    "Exceptions are handled with `try-except` blocks.  \n",
    "\n",
    "A `try-except` block asks Python to do something, but it also tells Python what to do if an exception is raised. When you use `try-except` blocks, your programs will continue running even if things start to go wrong. Instead of tracebacks, which can be confusing for users to read, users will see friendly error messages that you write.\n",
    "\n",
    "Let’s look at a simple error that causes Python to raise an exception. You probably know that it’s impossible to divide a number by zero, but let’s ask Python to do it anyway:"
   ]
  },
  {
   "cell_type": "code",
   "execution_count": 3,
   "metadata": {
    "slideshow": {
     "slide_type": "slide"
    }
   },
   "outputs": [
    {
     "name": "stdout",
     "output_type": "stream",
     "text": [
      "An error occured\n",
      "continue...\n"
     ]
    }
   ],
   "source": [
    "try:\n",
    "    print(5 / 0)\n",
    "except:\n",
    "    print('An error occured')\n",
    "else:\n",
    "    print('run rest of program') \n",
    "print('continue...')"
   ]
  },
  {
   "cell_type": "markdown",
   "metadata": {
    "slideshow": {
     "slide_type": "slide"
    }
   },
   "source": [
    "\n",
    "## Using `try-except` Blocks\n",
    "\n",
    "When you think an error may occur, you can write a try-except block to handle the exception that might be raised. You tell Python to try running some code, and you tell it what to do if the code results in a particular kind of exception."
   ]
  },
  {
   "cell_type": "code",
   "execution_count": 1,
   "metadata": {
    "slideshow": {
     "slide_type": "slide"
    }
   },
   "outputs": [
    {
     "name": "stdout",
     "output_type": "stream",
     "text": [
      "You can't divide by zero! <class 'ZeroDivisionError'>\n"
     ]
    }
   ],
   "source": [
    "try:\n",
    "    print(5/0)\n",
    "except ZeroDivisionError as ze:\n",
    "    print(\"You can't divide by zero!\",type(ze))"
   ]
  },
  {
   "cell_type": "code",
   "execution_count": 9,
   "metadata": {},
   "outputs": [
    {
     "name": "stdout",
     "output_type": "stream",
     "text": [
      "No such exception name 'Exc' is not defined\n"
     ]
    }
   ],
   "source": [
    "try:\n",
    "    raise Exc\n",
    "except (ZeroDivisionError,Exception) as e:\n",
    "    print(\"No such exception\", e)"
   ]
  },
  {
   "cell_type": "code",
   "execution_count": 5,
   "metadata": {},
   "outputs": [
    {
     "name": "stdout",
     "output_type": "stream",
     "text": [
      "Something went wrong\n"
     ]
    }
   ],
   "source": [
    "try:\n",
    "    print(5/0)\n",
    "except:\n",
    "    print(\"Something went wrong\")"
   ]
  },
  {
   "cell_type": "markdown",
   "metadata": {
    "slideshow": {
     "slide_type": "slide"
    }
   },
   "source": [
    "## The `else` Block\n",
    "\n",
    "We can make this program more error resistant by wrapping the line that might produce errors in a `try-except` block. The error occurs on the line that performs the division, so that is where we put the `try-except` block. The follownig example also includes an `else` block. *Any code that depends on the try block executing successfully goes in the `else` block.*\n"
   ]
  },
  {
   "cell_type": "code",
   "execution_count": 6,
   "metadata": {
    "slideshow": {
     "slide_type": "slide"
    }
   },
   "outputs": [
    {
     "name": "stdout",
     "output_type": "stream",
     "text": [
      "0.8571428571428571\n",
      "0.7777777777777778\n",
      "0.3333333333333333\n",
      "1.0\n",
      "2.0\n",
      "0.7\n",
      "0.125\n",
      "2.5\n",
      "2.0\n",
      "Cannot divide by 0!\n",
      "1.6666666666666667\n",
      "0.2857142857142857\n",
      "2.25\n",
      "5.0\n",
      "1.25\n",
      "0.9\n",
      "3.0\n",
      "1.3333333333333333\n",
      "0.8888888888888888\n",
      "1.1428571428571428\n"
     ]
    }
   ],
   "source": [
    "import random\n",
    "\n",
    "for i in range(0,20):\n",
    "    try:\n",
    "        result = random.randint(0,10) / random.randint(0,10)\n",
    "    except ZeroDivisionError: \n",
    "        print(\"Cannot divide by 0!\")\n",
    "    else: \n",
    "        print(result)"
   ]
  },
  {
   "cell_type": "markdown",
   "metadata": {
    "slideshow": {
     "slide_type": "slide"
    }
   },
   "source": [
    "## Multiple Exceptions\n",
    "\n",
    "In case the code in your `try` block can throw different types of exceptions, you can catch them with multiple `except` blocks. In case you need access to the exception object, you can assign it to a variable via the `as` keyword."
   ]
  },
  {
   "cell_type": "code",
   "execution_count": 8,
   "metadata": {
    "slideshow": {
     "slide_type": "slide"
    }
   },
   "outputs": [
    {
     "name": "stdout",
     "output_type": "stream",
     "text": [
      "division by zero\n"
     ]
    }
   ],
   "source": [
    "try:\n",
    "    with open('./Not_There.txt') as f_obj:\n",
    "        contents = f_obj.read()\n",
    "    print(5/0)\n",
    "except ZeroDivisionError as e:\n",
    "    print(e)\n",
    "except FileNotFoundError as e:\n",
    "    print(e)\n",
    "else:\n",
    "    print(\"Everything went well...\")"
   ]
  },
  {
   "cell_type": "markdown",
   "metadata": {
    "slideshow": {
     "slide_type": "slide"
    }
   },
   "source": [
    "Alternatively, you can 'go up in the exception hierarchy' by catching all exceptions as in the following. However, you may no catch errors, that you would have liked to crash your program."
   ]
  },
  {
   "cell_type": "code",
   "execution_count": 7,
   "metadata": {
    "slideshow": {
     "slide_type": "slide"
    }
   },
   "outputs": [
    {
     "name": "stdout",
     "output_type": "stream",
     "text": [
      "[Errno 2] No such file or directory: './Not_There.txt'\n"
     ]
    }
   ],
   "source": [
    "try:\n",
    "    #print(5/0)\n",
    "    with open('./Not_There.txt') as f_obj:\n",
    "        contents = f_obj.read()\n",
    "except Exception as e:\n",
    "    print(e)\n",
    "else:\n",
    "    print(\"Everything went well...\")"
   ]
  },
  {
   "cell_type": "markdown",
   "metadata": {
    "slideshow": {
     "slide_type": "slide"
    }
   },
   "source": [
    "# Raising and Implementing Exceptions\n",
    "\n",
    "In case you need to raise your own exceptions, you can do so with the help of the `raise` keyword. To implement your own exception you have to implement a subclass of the type of exception that is closest to your new type of error as illustrated in the following.\n"
   ]
  },
  {
   "cell_type": "code",
   "execution_count": 2,
   "metadata": {
    "slideshow": {
     "slide_type": "slide"
    }
   },
   "outputs": [
    {
     "ename": "NoOneValueError",
     "evalue": "Oh no, 1 is not in [2, 7, 8, 10, 'aha']!",
     "output_type": "error",
     "traceback": [
      "\u001b[0;31m---------------------------------------------------------------------------\u001b[0m",
      "\u001b[0;31mNoOneValueError\u001b[0m                           Traceback (most recent call last)",
      "\u001b[0;32m<ipython-input-2-5171fb50bb78>\u001b[0m in \u001b[0;36m<module>\u001b[0;34m\u001b[0m\n\u001b[1;32m      9\u001b[0m     \u001b[0mprint\u001b[0m\u001b[0;34m(\u001b[0m\u001b[0;34m'Alright!'\u001b[0m\u001b[0;34m)\u001b[0m\u001b[0;34m\u001b[0m\u001b[0;34m\u001b[0m\u001b[0m\n\u001b[1;32m     10\u001b[0m \u001b[0;32melse\u001b[0m\u001b[0;34m:\u001b[0m\u001b[0;34m\u001b[0m\u001b[0;34m\u001b[0m\u001b[0m\n\u001b[0;32m---> 11\u001b[0;31m     \u001b[0;32mraise\u001b[0m \u001b[0mNoOneValueError\u001b[0m\u001b[0;34m(\u001b[0m\u001b[0;34mf'Oh no, {value} is not in {some_data}!'\u001b[0m\u001b[0;34m)\u001b[0m\u001b[0;34m\u001b[0m\u001b[0;34m\u001b[0m\u001b[0m\n\u001b[0m",
      "\u001b[0;31mNoOneValueError\u001b[0m: Oh no, 1 is not in [2, 7, 8, 10, 'aha']!"
     ]
    }
   ],
   "source": [
    "class NoOneValueError(ValueError):\n",
    "    \n",
    "    def __init__(self, *args, **kwargs):\n",
    "        ValueError.__init__(self, *args, **kwargs)\n",
    "\n",
    "value = 1\n",
    "some_data = [2, 7, 8, 10, 'aha']\n",
    "if value in some_data:\n",
    "    print('Alright!')\n",
    "else:\n",
    "    raise NoOneValueError(f'Oh no, {value} is not in {some_data}!')"
   ]
  },
  {
   "cell_type": "markdown",
   "metadata": {},
   "source": [
    "or in simpler ways just extend the Exception class with no implementation like this:  \n",
    "```python\n",
    "class InvalidArgumentException(Exception):\n",
    "    pass\n",
    "```"
   ]
  },
  {
   "cell_type": "code",
   "execution_count": 13,
   "metadata": {},
   "outputs": [
    {
     "ename": "InvalidArgumentException",
     "evalue": "",
     "output_type": "error",
     "traceback": [
      "\u001b[0;31m---------------------------------------------------------------------------\u001b[0m",
      "\u001b[0;31mInvalidArgumentException\u001b[0m                  Traceback (most recent call last)",
      "\u001b[0;32m<ipython-input-13-e3136fb950d5>\u001b[0m in \u001b[0;36m<module>\u001b[0;34m\u001b[0m\n\u001b[1;32m      2\u001b[0m     \u001b[0;32mpass\u001b[0m\u001b[0;34m\u001b[0m\u001b[0;34m\u001b[0m\u001b[0m\n\u001b[1;32m      3\u001b[0m \u001b[0;34m\u001b[0m\u001b[0m\n\u001b[0;32m----> 4\u001b[0;31m \u001b[0;32mraise\u001b[0m \u001b[0mInvalidArgumentException\u001b[0m\u001b[0;34m(\u001b[0m\u001b[0;34m)\u001b[0m\u001b[0;34m\u001b[0m\u001b[0;34m\u001b[0m\u001b[0m\n\u001b[0m",
      "\u001b[0;31mInvalidArgumentException\u001b[0m: "
     ]
    }
   ],
   "source": [
    "class InvalidArgumentException(Exception):\n",
    "    pass\n",
    "\n",
    "raise InvalidArgumentException()"
   ]
  },
  {
   "cell_type": "markdown",
   "metadata": {},
   "source": [
    "## Exercise\n",
    "1. Create a class called: Person with a constructor that takes a string: name.\n",
    "2. Check if name contains only letters and each new word starts with a capital letter. If this is not the case raise an InvalidArgumentException (your own exception here)\n",
    "\n",
    "3. Test your new class by making 2 instances (one with a name, that follows the rules and another that violates them)"
   ]
  }
 ],
 "metadata": {
  "celltoolbar": "Slideshow",
  "kernelspec": {
   "display_name": "Python 3",
   "language": "python",
   "name": "python3"
  },
  "language_info": {
   "codemirror_mode": {
    "name": "ipython",
    "version": 3
   },
   "file_extension": ".py",
   "mimetype": "text/x-python",
   "name": "python",
   "nbconvert_exporter": "python",
   "pygments_lexer": "ipython3",
   "version": "3.7.6"
  },
  "varInspector": {
   "cols": {
    "lenName": 16,
    "lenType": 16,
    "lenVar": 40
   },
   "kernels_config": {
    "python": {
     "delete_cmd_postfix": "",
     "delete_cmd_prefix": "del ",
     "library": "var_list.py",
     "varRefreshCmd": "print(var_dic_list())"
    },
    "r": {
     "delete_cmd_postfix": ") ",
     "delete_cmd_prefix": "rm(",
     "library": "var_list.r",
     "varRefreshCmd": "cat(var_dic_list()) "
    }
   },
   "types_to_exclude": [
    "module",
    "function",
    "builtin_function_or_method",
    "instance",
    "_Feature"
   ],
   "window_display": false
  }
 },
 "nbformat": 4,
 "nbformat_minor": 2
}
